Workbook

Sheet Sample DEC
F1: Duration | H1: Month
H2: Development | J2: Construction- | M2: Construction
H3: 1 | I3: =H3+1 -> 2 | J3: =I3+1 -> 3 | K3: =J3+1 -> 4 | L3: =K3+1 -> 5 | M3: =L3+1 -> 6 | N3: =M3+1 -> 7 | O3: =N3+1 -> 8 | P3: =O3+1 -> 9 | ... U3: =T3+1 -> 14
A4: 1. Permitting & Regulatory Approvals | F4: 5
B5: Construction permit | D5: AAB | E5: Jelmer | F5: 5 | H5: 1 | I5: 1 | J5: 1 | K5: 1 | L5: 1
B6: BESS permit | I6: 1 | J6: 1
A7: 2. Procurement & Contracting | F7: 9
B8: EPC selection | D8: Jeroen | E8: Jelmer | F8: 2 | I8: 1
B9: MEP vendors | D9: Jeroen | E9: Jelmer | F9: 2 | I9: 1
B10: Long Load Items | J10: 1 | K10: 1 | L10: 1 | M10: 1 | N10: 1 | O10: 1 | P10: 1 | Q10: 1
A12: 3. Bess development | F12: 7
B13: Concrete + foundation | D13: Civil contractor | E13: Jelmer | F13: 2 | M13: 1 | N13: 1
B14: Transformer | D14: E contractor | E14: Jelmer | F14: 1 | N14: 1
B15: Supplier | D15: BESS contractor | E15: Jelmer | F15: 1 | I15: 1
B16: Leat time | D16: BESS contractor | F16: 5 | K16: 1 | L16: 1 | M16: 1 | N16: 1 | O16: 1
B17: Installation | D17: BESS contractor | E17: Jelmer | F17: 1 | P17: 1
A18: 4. Design & Engineering | F18: 5
B19: Riba 2 | D19: AAB | E19: DJ | F19: 2 | H19: 1 | I19: 1
B20: Riba 3 | C20: EPC | D20: Design Contractor | E20: DJ | F20: 2 | J20: 1
B21: Riba 4 | C21: EPC | D21: Design Contractor | E21: DJ | F21: 4 | K21: 1 | L21: 1
B22: design freeze | E22: DJ/Jeroen | L22: 1
A23: 5. Control | F23: 7
B24: EMS strategy | E24: DJ | J24: 1 | K24: 1
B25: EMS installation | E25: DJ | M25: 1 | N25: 1
B26: EMS testing | E26: DJ | O26: 1
B27: EMS Commissioning | E27: DJ | P27: 1
B28: BMS installation | E28: DJ
B29: BMS testing | E29: DJ
B30: BMS Commissioning | E30: DJ
A31: 6. Construction (Shell & Core) | F31: 5.5
B32: Concrete + foundation | C32: EPC | D32: Civil contractor | E32: Jeroen | F32: 2 | M32: 1
B33: Shell + lights/doors/ | C33: EPC | D33: Civil contractor | E33: Jeroen | F33: 2 | N33: 1 | O33: 1
B34: Transformers, UPS, Main distribution | C34: EPC | D34: E contractor | E34: Jeroen | F34: 1.5 | Q34: 1 | R34: 0.5
B35: Power cables & Main busbars | C35: EPC | D35: E contractor | E35: Jeroen | F35: 1.5 | Q35: 1 | R35: 0.5
B36: Heat pumps | C36: EPC | D36: W contractor | E36: Jeroen | F36: 2 | Q36: 1 | R36: 1
B37: water works | C37: EPC | D37: W contractor | E37: Jeroen | F37: 2 | Q37: 1 | R37: 1
A38: 7. Customer Fit-Out (White Space + MEP) | F38: 1 | S38: 1
B39: Whitespace fitout incl "Run" | C39: EPC | D39: Civil contractor | E39: Jeroen | F39: 0.5 | S39: 0.5
B40: Distribution Busbar | C40: EPC | D40: E contractor | E40: Jeroen | F40: 1 | S40: 1
B41: Air cooling | C41: EPC | D41: W contractor | E41: Jeroen | F41: 1 | S41: 1
...

Sheet Sample BESS
F1: Duration | G1: CAPEX | H1: Month
H2: Growth | K2: Development | N2: Construction
H3: =I3-1 -> -2 | I3: =J3-1 -> -1 | J3: 0 | K3: =J3+1 -> 1 | L3: =K3+1 -> 2 | M3: =L3+1 -> 3 | N3: =M3+1 -> 4 | O3: 5 | P3: 6
A4: 2. Land & Grid Securing
B5: HoT | D5: Co | F5: 1 | J5: 1
B6: Grid | D6: Co | F6: 2 | H6: 1 | I6: 1
A7: 3. Permitting & Regulatory Approvals
B8: BESS permit | D8: Jelmer | F8: 6 | K8: 1 | L8: 1 | M8: 1
A9: 6A Bess development
B10: Concrete + foundation | C10: BESS contractor | D10: Jelmer | F10: 2 | N10: 1
B11: Transformer | C11: BESS contractor | D11: Jelmer | F11: 1 | O11: 1
B12: Supplier | C12: BESS contractor | D12: Jelmer | F12: 1 | K12: 1
B13: Leat time | F13: 5 | L13: 1 | M13: 1 | N13: 1 | O13: 1 | P13: 1
B14: Installation | C14: BESS contractor | D14: Jelmer | F14: 1 | P14: 1
A15: Control
B16: EMS strategy | D16: DJ | M16: 1
B17: EMS installation | D17: DJ | P17: 1
B18: EMS testing | D18: DJ | P18: 1
B19: EMS Commissioning | D19: DJ
A21: CAPEX | K21: =SUMPRODUCT($G$22:$G$36,K22:K36) -> 2.2723968 | L21: =SUMPRODUCT($G$22:$G$36,L22:L36) -> 0 | M21: =SUMPRODUCT($G$22:$G$36,M22:M36) -> 0 | N21: =SUMPRODUCT($G$22:$G$36,N22:N36) -> 0 | O21: =SUMPRODUCT($G$22:$G$36,O22:O36) -> 0 | P21: =SUMPRODUCT($G$22:$G$36,P22:P36) -> 0.2391552
B22: BESS (battery energy storage system) | C22: =1782960+178000+32000 -> 1992960 | G22: =C22*(1+$C$24)/1000000 -> 2.391552 | K22: 0.9 | P22: 0.1
B23: Concrete + foundation | C23: 100000 | G23: =C23*(1+$C$24)/1000000 -> 0.12 | K23: 1
B24: Contingency + Installation | C24: 0.2
B25: Total | G25: =SUM(G13:G23) -> 2.511552
B26: E/MW | G26: =G25/4 -> 0.627888

Sheet Planning 2026_2027
A1: Year | E1: Start month | I1: 2026 | J1: =I1 -> 2026 | K1: =J1 -> 2026 | L1: =K1 -> 2026 | M1: =L1 -> 2026 | N1: =M1 -> 2026 | O1: =N1 -> 2026 | P1: =O1 -> 2026 | Q1: =P1 -> 2026 | ... T1: =S1 -> 2026 | U1: =I1+1 -> 2027 | V1: =J1+1 -> 2027 | W1: =K1+1 -> 2027 | X1: =L1+1 -> 2027 | Y1: =M1+1 -> 2027 | Z1: =N1+1 -> 2027 | AA1: =O1+1 -> 2027 | AB1: =P1+1 -> 2027 | ... AF1: =T1+1 -> 2027
A2: Month | E2: D | F2: C- | G2: C | H2: Done | I2: 1 | J2: =I2+1 -> 2 | K2: =J2+1 -> 3 | L2: =K2+1 -> 4 | M2: =L2+1 -> 5 | N2: =M2+1 -> 6 | O2: =N2+1 -> 7 | P2: =O2+1 -> 8 | Q2: =P2+1 -> 9 | ... AI2: =AH2+1 -> 27
B3: MW IT | C3: Type | E3: 1 | F3: 3 | G3: 6 | H3: 14 | W3: =IF(W$2<$E3,"",IF(W$2<$F3,"D",IF(W$2<$G3,"C-",IF(W$2<=$H3,"C","")))) | X3: =IF(X$2<$E3,"",IF(X$2<$F3,"D",IF(X$2<$G3,"C-",IF(X$2<=$H3,"C","")))) | Y3: =IF(Y$2<$E3,"",IF(Y$2<$F3,"D",IF(Y$2<$G3,"C-",IF(Y$2<=$H3,"C","")))) | Z3: =IF(Z$2<$E3,"",IF(Z$2<$F3,"D",IF(Z$2<$G3,"C-",IF(Z$2<=$H3,"C","")))) | AA3: =IF(AA$2<$E3,"",IF(AA$2<$F3,"D",IF(AA$2<$G3,"C-",IF(AA$2<=$H3,"C","")))) | AB3: =IF(AB$2<$E3,"",IF(AB$2<$F3,"D",IF(AB$2<$G3,"C-",IF(AB$2<=$H3,"C","")))) | AC3: =IF(AC$2<$E3,"",IF(AC$2<$F3,"D",IF(AC$2<$G3,"C-",IF(AC$2<=$H3,"C","")))) | AD3: =IF(AD$2<$E3,"",IF(AD$2<$F3,"D",IF(AD$2<$G3,"C-",IF(AD$2<=$H3,"C","")))) | ... AI3: =IF(AI$2<$E3,"",IF(AI$2<$F3,"D",IF(AI$2<$G3,"C-",IF(AI$2<=$H3,"C",""))))
A4: DC 1 (Powergrow) | B4: 4 | C4: EPC | E4: 1 | F4: 3 | G4: 6 | H4: 14 | I4: =IF(I$2<$E4,"",IF(I$2<$F4,"D",IF(I$2<$G4,"C-",IF(I$2<=$H4,"C","")))) -> D | J4: =IF(J$2<$E4,"",IF(J$2<$F4,"D",IF(J$2<$G4,"C-",IF(J$2<=$H4,"C","")))) -> D | K4: =IF(K$2<$E4,"",IF(K$2<$F4,"D",IF(K$2<$G4,"C-",IF(K$2<=$H4,"C","")))) -> C- | L4: =IF(L$2<$E4,"",IF(L$2<$F4,"D",IF(L$2<$G4,"C-",IF(L$2<=$H4,"C","")))) -> C- | M4: =IF(M$2<$E4,"",IF(M$2<$F4,"D",IF(M$2<$G4,"C-",IF(M$2<=$H4,"C","")))) -> C- | N4: =IF(N$2<$E4,"",IF(N$2<$F4,"D",IF(N$2<$G4,"C-",IF(N$2<=$H4,"C","")))) -> C | O4: =IF(O$2<$E4,"",IF(O$2<$F4,"D",IF(O$2<$G4,"C-",IF(O$2<=$H4,"C","")))) -> C | P4: =IF(P$2<$E4,"",IF(P$2<$F4,"D",IF(P$2<$G4,"C-",IF(P$2<=$H4,"C","")))) -> C | ... AI4: =IF(AI$2<$E4,"",IF(AI$2<$F4,"D",IF(AI$2<$G4,"C-",IF(AI$2<=$H4,"C",""))))
A5: DC 2 (EPFlora) | B5: 4 | C5: EPC | E5: 1 | F5: 5 | G5: 10 | H5: 20 | I5: =IF(I$2<$E5,"",IF(I$2<$F5,"D",IF(I$2<$G5,"C-",IF(I$2<=$H5,"C","")))) -> D | J5: =IF(J$2<$E5,"",IF(J$2<$F5,"D",IF(J$2<$G5,"C-",IF(J$2<=$H5,"C","")))) -> D | K5: =IF(K$2<$E5,"",IF(K$2<$F5,"D",IF(K$2<$G5,"C-",IF(K$2<=$H5,"C","")))) -> D | L5: =IF(L$2<$E5,"",IF(L$2<$F5,"D",IF(L$2<$G5,"C-",IF(L$2<=$H5,"C","")))) -> D | M5: =IF(M$2<$E5,"",IF(M$2<$F5,"D",IF(M$2<$G5,"C-",IF(M$2<=$H5,"C","")))) -> C- | N5: =IF(N$2<$E5,"",IF(N$2<$F5,"D",IF(N$2<$G5,"C-",IF(N$2<=$H5,"C","")))) -> C- | O5: =IF(O$2<$E5,"",IF(O$2<$F5,"D",IF(O$2<$G5,"C-",IF(O$2<=$H5,"C","")))) -> C- | P5: =IF(P$2<$E5,"",IF(P$2<$F5,"D",IF(P$2<$G5,"C-",IF(P$2<=$H5,"C","")))) -> C- | ... AI5: =IF(AI$2<$E5,"",IF(AI$2<$F5,"D",IF(AI$2<$G5,"C-",IF(AI$2<=$H5,"C",""))))
A6: DC 3 | B6: 4 | C6: non-EPC | E6: 2 | F6: 8 | G6: 14 | H6: 25 | I6: =IF(I$2<$E6,"",IF(I$2<$F6,"D",IF(I$2<$G6,"C-",IF(I$2<=$H6,"C","")))) | J6: =IF(J$2<$E6,"",IF(J$2<$F6,"D",IF(J$2<$G6,"C-",IF(J$2<=$H6,"C","")))) -> D | K6: =IF(K$2<$E6,"",IF(K$2<$F6,"D",IF(K$2<$G6,"C-",IF(K$2<=$H6,"C","")))) -> D | L6: =IF(L$2<$E6,"",IF(L$2<$F6,"D",IF(L$2<$G6,"C-",IF(L$2<=$H6,"C","")))) -> D | M6: =IF(M$2<$E6,"",IF(M$2<$F6,"D",IF(M$2<$G6,"C-",IF(M$2<=$H6,"C","")))) -> D | N6: =IF(N$2<$E6,"",IF(N$2<$F6,"D",IF(N$2<$G6,"C-",IF(N$2<=$H6,"C","")))) -> D | O6: =IF(O$2<$E6,"",IF(O$2<$F6,"D",IF(O$2<$G6,"C-",IF(O$2<=$H6,"C","")))) -> D | P6: =IF(P$2<$E6,"",IF(P$2<$F6,"D",IF(P$2<$G6,"C-",IF(P$2<=$H6,"C","")))) -> C- | ... AI6: =IF(AI$2<$E6,"",IF(AI$2<$F6,"D",IF(AI$2<$G6,"C-",IF(AI$2<=$H6,"C",""))))
A7: DC 4 | B7: 8 | C7: EPC | E7: 6 | F7: 12 | G7: 18 | H7: 27 | I7: =IF(I$2<$E7,"",IF(I$2<$F7,"D",IF(I$2<$G7,"C-",IF(I$2<=$H7,"C","")))) | J7: =IF(J$2<$E7,"",IF(J$2<$F7,"D",IF(J$2<$G7,"C-",IF(J$2<=$H7,"C","")))) | K7: =IF(K$2<$E7,"",IF(K$2<$F7,"D",IF(K$2<$G7,"C-",IF(K$2<=$H7,"C","")))) | L7: =IF(L$2<$E7,"",IF(L$2<$F7,"D",IF(L$2<$G7,"C-",IF(L$2<=$H7,"C","")))) | M7: =IF(M$2<$E7,"",IF(M$2<$F7,"D",IF(M$2<$G7,"C-",IF(M$2<=$H7,"C","")))) | N7: =IF(N$2<$E7,"",IF(N$2<$F7,"D",IF(N$2<$G7,"C-",IF(N$2<=$H7,"C","")))) -> D | O7: =IF(O$2<$E7,"",IF(O$2<$F7,"D",IF(O$2<$G7,"C-",IF(O$2<=$H7,"C","")))) -> D | P7: =IF(P$2<$E7,"",IF(P$2<$F7,"D",IF(P$2<$G7,"C-",IF(P$2<=$H7,"C","")))) -> D | ... AI7: =IF(AI$2<$E7,"",IF(AI$2<$F7,"D",IF(AI$2<$G7,"C-",IF(AI$2<=$H7,"C","")))) -> C
A8: DC 5 | B8: 8 | C8: EPC | E8: 6 | F8: 12 | G8: 18 | H8: 27 | I8: =IF(I$2<$E8,"",IF(I$2<$F8,"D",IF(I$2<$G8,"C-",IF(I$2<=$H8,"C","")))) | J8: =IF(J$2<$E8,"",IF(J$2<$F8,"D",IF(J$2<$G8,"C-",IF(J$2<=$H8,"C","")))) | K8: =IF(K$2<$E8,"",IF(K$2<$F8,"D",IF(K$2<$G8,"C-",IF(K$2<=$H8,"C","")))) | L8: =IF(L$2<$E8,"",IF(L$2<$F8,"D",IF(L$2<$G8,"C-",IF(L$2<=$H8,"C","")))) | M8: =IF(M$2<$E8,"",IF(M$2<$F8,"D",IF(M$2<$G8,"C-",IF(M$2<=$H8,"C","")))) | N8: =IF(N$2<$E8,"",IF(N$2<$F8,"D",IF(N$2<$G8,"C-",IF(N$2<=$H8,"C","")))) -> D | O8: =IF(O$2<$E8,"",IF(O$2<$F8,"D",IF(O$2<$G8,"C-",IF(O$2<=$H8,"C","")))) -> D | P8: =IF(P$2<$E8,"",IF(P$2<$F8,"D",IF(P$2<$G8,"C-",IF(P$2<=$H8,"C","")))) -> D | ... AI8: =IF(AI$2<$E8,"",IF(AI$2<$F8,"D",IF(AI$2<$G8,"C-",IF(AI$2<=$H8,"C","")))) -> C
B9: MW Utility
A10: BESS 1 | B10: 5 | D10: DC 1 | E10: 2 | F10: 5 | G10: =E10+3 -> 5 | H10: 7 | I10: =IF(I$2<$E10,"",IF(I$2<$F10,"D",IF(I$2<$G10,"C-",IF(I$2<=$H10,"C","")))) | J10: =IF(J$2<$E10,"",IF(J$2<$F10,"D",IF(J$2<$G10,"C-",IF(J$2<=$H10,"C","")))) -> D | K10: =IF(K$2<$E10,"",IF(K$2<$F10,"D",IF(K$2<$G10,"C-",IF(K$2<=$H10,"C","")))) -> D | L10: =IF(L$2<$E10,"",IF(L$2<$F10,"D",IF(L$2<$G10,"C-",IF(L$2<=$H10,"C","")))) -> D | M10: =IF(M$2<$E10,"",IF(M$2<$F10,"D",IF(M$2<$G10,"C-",IF(M$2<=$H10,"C","")))) -> C | N10: =IF(N$2<$E10,"",IF(N$2<$F10,"D",IF(N$2<$G10,"C-",IF(N$2<=$H10,"C","")))) -> C | O10: =IF(O$2<$E10,"",IF(O$2<$F10,"D",IF(O$2<$G10,"C-",IF(O$2<=$H10,"C","")))) -> C | P10: =IF(P$2<$E10,"",IF(P$2<$F10,"D",IF(P$2<$G10,"C-",IF(P$2<=$H10,"C","")))) | ... AI10: =IF(AI$2<$E10,"",IF(AI$2<$F10,"D",IF(AI$2<$G10,"C-",IF(AI$2<=$H10,"C",""))))
A11: BESS 2 | B11: 5 | D11: DC 2 | E11: 3 | F11: =G11 -> 6 | G11: =E11+3 -> 6 | H11: 8 | I11: =IF(I$2<$E11,"",IF(I$2<$F11,"D",IF(I$2<$G11,"C-",IF(I$2<=$H11,"C","")))) | J11: =IF(J$2<$E11,"",IF(J$2<$F11,"D",IF(J$2<$G11,"C-",IF(J$2<=$H11,"C","")))) | K11: =IF(K$2<$E11,"",IF(K$2<$F11,"D",IF(K$2<$G11,"C-",IF(K$2<=$H11,"C","")))) -> D | L11: =IF(L$2<$E11,"",IF(L$2<$F11,"D",IF(L$2<$G11,"C-",IF(L$2<=$H11,"C","")))) -> D | M11: =IF(M$2<$E11,"",IF(M$2<$F11,"D",IF(M$2<$G11,"C-",IF(M$2<=$H11,"C","")))) -> D | N11: =IF(N$2<$E11,"",IF(N$2<$F11,"D",IF(N$2<$G11,"C-",IF(N$2<=$H11,"C","")))) -> C | O11: =IF(O$2<$E11,"",IF(O$2<$F11,"D",IF(O$2<$G11,"C-",IF(O$2<=$H11,"C","")))) -> C | P11: =IF(P$2<$E11,"",IF(P$2<$F11,"D",IF(P$2<$G11,"C-",IF(P$2<=$H11,"C","")))) -> C | ... AI11: =IF(AI$2<$E11,"",IF(AI$2<$F11,"D",IF(AI$2<$G11,"C-",IF(AI$2<=$H11,"C",""))))
A12: BESS 3 | B12: 5 | D12: DC 3 | E12: 5 | F12: =G12 -> 8 | G12: =E12+3 -> 8 | H12: =G12+2 -> 10 | I12: =IF(I$2<$E12,"",IF(I$2<$F12,"D",IF(I$2<$G12,"C-",IF(I$2<=$H12,"C","")))) | J12: =IF(J$2<$E12,"",IF(J$2<$F12,"D",IF(J$2<$G12,"C-",IF(J$2<=$H12,"C","")))) | K12: =IF(K$2<$E12,"",IF(K$2<$F12,"D",IF(K$2<$G12,"C-",IF(K$2<=$H12,"C","")))) | L12: =IF(L$2<$E12,"",IF(L$2<$F12,"D",IF(L$2<$G12,"C-",IF(L$2<=$H12,"C","")))) | M12: =IF(M$2<$E12,"",IF(M$2<$F12,"D",IF(M$2<$G12,"C-",IF(M$2<=$H12,"C","")))) -> D | N12: =IF(N$2<$E12,"",IF(N$2<$F12,"D",IF(N$2<$G12,"C-",IF(N$2<=$H12,"C","")))) -> D | O12: =IF(O$2<$E12,"",IF(O$2<$F12,"D",IF(O$2<$G12,"C-",IF(O$2<=$H12,"C","")))) -> D | P12: =IF(P$2<$E12,"",IF(P$2<$F12,"D",IF(P$2<$G12,"C-",IF(P$2<=$H12,"C","")))) -> C | ... AI12: =IF(AI$2<$E12,"",IF(AI$2<$F12,"D",IF(AI$2<$G12,"C-",IF(AI$2<=$H12,"C",""))))
A13: BESS 4 | B13: 10 | D13: DC 4 | E13: 6 | F13: =G13 -> 9 | G13: =E13+3 -> 9 | H13: =G13+2 -> 11 | I13: =IF(I$2<$E13,"",IF(I$2<$F13,"D",IF(I$2<$G13,"C-",IF(I$2<=$H13,"C","")))) | J13: =IF(J$2<$E13,"",IF(J$2<$F13,"D",IF(J$2<$G13,"C-",IF(J$2<=$H13,"C","")))) | K13: =IF(K$2<$E13,"",IF(K$2<$F13,"D",IF(K$2<$G13,"C-",IF(K$2<=$H13,"C","")))) | L13: =IF(L$2<$E13,"",IF(L$2<$F13,"D",IF(L$2<$G13,"C-",IF(L$2<=$H13,"C","")))) | M13: =IF(M$2<$E13,"",IF(M$2<$F13,"D",IF(M$2<$G13,"C-",IF(M$2<=$H13,"C","")))) | N13: =IF(N$2<$E13,"",IF(N$2<$F13,"D",IF(N$2<$G13,"C-",IF(N$2<=$H13,"C","")))) -> D | O13: =IF(O$2<$E13,"",IF(O$2<$F13,"D",IF(O$2<$G13,"C-",IF(O$2<=$H13,"C","")))) -> D | P13: =IF(P$2<$E13,"",IF(P$2<$F13,"D",IF(P$2<$G13,"C-",IF(P$2<=$H13,"C","")))) -> D | ... AI13: =IF(AI$2<$E13,"",IF(AI$2<$F13,"D",IF(AI$2<$G13,"C-",IF(AI$2<=$H13,"C",""))))
A14: BESS 5 | B14: 10 | D14: DC 5 | E14: 7 | F14: =G14 -> 10 | G14: =E14+3 -> 10 | H14: =G14+2 -> 12 | I14: =IF(I$2<$E14,"",IF(I$2<$F14,"D",IF(I$2<$G14,"C-",IF(I$2<=$H14,"C","")))) | J14: =IF(J$2<$E14,"",IF(J$2<$F14,"D",IF(J$2<$G14,"C-",IF(J$2<=$H14,"C","")))) | K14: =IF(K$2<$E14,"",IF(K$2<$F14,"D",IF(K$2<$G14,"C-",IF(K$2<=$H14,"C","")))) | L14: =IF(L$2<$E14,"",IF(L$2<$F14,"D",IF(L$2<$G14,"C-",IF(L$2<=$H14,"C","")))) | M14: =IF(M$2<$E14,"",IF(M$2<$F14,"D",IF(M$2<$G14,"C-",IF(M$2<=$H14,"C","")))) | N14: =IF(N$2<$E14,"",IF(N$2<$F14,"D",IF(N$2<$G14,"C-",IF(N$2<=$H14,"C","")))) | O14: =IF(O$2<$E14,"",IF(O$2<$F14,"D",IF(O$2<$G14,"C-",IF(O$2<=$H14,"C","")))) -> D | P14: =IF(P$2<$E14,"",IF(P$2<$F14,"D",IF(P$2<$G14,"C-",IF(P$2<=$H14,"C","")))) -> D | ... AI14: =IF(AI$2<$E14,"",IF(AI$2<$F14,"D",IF(AI$2<$G14,"C-",IF(AI$2<=$H14,"C",""))))
A15: BESS 6 | B15: 5 | E15: 8 | F15: =G15 -> 11 | G15: =E15+3 -> 11 | H15: =G15+2 -> 13 | I15: =IF(I$2<$E15,"",IF(I$2<$F15,"D",IF(I$2<$G15,"C-",IF(I$2<=$H15,"C","")))) | J15: =IF(J$2<$E15,"",IF(J$2<$F15,"D",IF(J$2<$G15,"C-",IF(J$2<=$H15,"C","")))) | K15: =IF(K$2<$E15,"",IF(K$2<$F15,"D",IF(K$2<$G15,"C-",IF(K$2<=$H15,"C","")))) | L15: =IF(L$2<$E15,"",IF(L$2<$F15,"D",IF(L$2<$G15,"C-",IF(L$2<=$H15,"C","")))) | M15: =IF(M$2<$E15,"",IF(M$2<$F15,"D",IF(M$2<$G15,"C-",IF(M$2<=$H15,"C","")))) | N15: =IF(N$2<$E15,"",IF(N$2<$F15,"D",IF(N$2<$G15,"C-",IF(N$2<=$H15,"C","")))) | O15: =IF(O$2<$E15,"",IF(O$2<$F15,"D",IF(O$2<$G15,"C-",IF(O$2<=$H15,"C","")))) | P15: =IF(P$2<$E15,"",IF(P$2<$F15,"D",IF(P$2<$G15,"C-",IF(P$2<=$H15,"C","")))) -> D | ... AI15: =IF(AI$2<$E15,"",IF(AI$2<$F15,"D",IF(AI$2<$G15,"C-",IF(AI$2<=$H15,"C",""))))
A16: BESS 7 | B16: 10 | E16: 9 | F16: =G16 -> 12 | G16: =E16+3 -> 12 | H16: =G16+2 -> 14 | I16: =IF(I$2<$E16,"",IF(I$2<$F16,"D",IF(I$2<$G16,"C-",IF(I$2<=$H16,"C","")))) | J16: =IF(J$2<$E16,"",IF(J$2<$F16,"D",IF(J$2<$G16,"C-",IF(J$2<=$H16,"C","")))) | K16: =IF(K$2<$E16,"",IF(K$2<$F16,"D",IF(K$2<$G16,"C-",IF(K$2<=$H16,"C","")))) | L16: =IF(L$2<$E16,"",IF(L$2<$F16,"D",IF(L$2<$G16,"C-",IF(L$2<=$H16,"C","")))) | M16: =IF(M$2<$E16,"",IF(M$2<$F16,"D",IF(M$2<$G16,"C-",IF(M$2<=$H16,"C","")))) | N16: =IF(N$2<$E16,"",IF(N$2<$F16,"D",IF(N$2<$G16,"C-",IF(N$2<=$H16,"C","")))) | O16: =IF(O$2<$E16,"",IF(O$2<$F16,"D",IF(O$2<$G16,"C-",IF(O$2<=$H16,"C","")))) | P16: =IF(P$2<$E16,"",IF(P$2<$F16,"D",IF(P$2<$G16,"C-",IF(P$2<=$H16,"C","")))) | ... AI16: =IF(AI$2<$E16,"",IF(AI$2<$F16,"D",IF(AI$2<$G16,"C-",IF(AI$2<=$H16,"C",""))))
A17: BESS 8 | B17: 10 | E17: 10 | F17: =G17 -> 13 | G17: =E17+3 -> 13 | H17: =G17+2 -> 15 | I17: =IF(I$2<$E17,"",IF(I$2<$F17,"D",IF(I$2<$G17,"C-",IF(I$2<=$H17,"C","")))) | J17: =IF(J$2<$E17,"",IF(J$2<$F17,"D",IF(J$2<$G17,"C-",IF(J$2<=$H17,"C","")))) | K17: =IF(K$2<$E17,"",IF(K$2<$F17,"D",IF(K$2<$G17,"C-",IF(K$2<=$H17,"C","")))) | L17: =IF(L$2<$E17,"",IF(L$2<$F17,"D",IF(L$2<$G17,"C-",IF(L$2<=$H17,"C","")))) | M17: =IF(M$2<$E17,"",IF(M$2<$F17,"D",IF(M$2<$G17,"C-",IF(M$2<=$H17,"C","")))) | N17: =IF(N$2<$E17,"",IF(N$2<$F17,"D",IF(N$2<$G17,"C-",IF(N$2<=$H17,"C","")))) | O17: =IF(O$2<$E17,"",IF(O$2<$F17,"D",IF(O$2<$G17,"C-",IF(O$2<=$H17,"C","")))) | P17: =IF(P$2<$E17,"",IF(P$2<$F17,"D",IF(P$2<$G17,"C-",IF(P$2<=$H17,"C","")))) | ... AI17: =IF(AI$2<$E17,"",IF(AI$2<$F17,"D",IF(AI$2<$G17,"C-",IF(AI$2<=$H17,"C",""))))
A18: BESS 9 | B18: 5 | E18: 11 | F18: =G18 -> 14 | G18: =E18+3 -> 14 | H18: =G18+2 -> 16 | I18: =IF(I$2<$E18,"",IF(I$2<$F18,"D",IF(I$2<$G18,"C-",IF(I$2<=$H18,"C","")))) | J18: =IF(J$2<$E18,"",IF(J$2<$F18,"D",IF(J$2<$G18,"C-",IF(J$2<=$H18,"C","")))) | K18: =IF(K$2<$E18,"",IF(K$2<$F18,"D",IF(K$2<$G18,"C-",IF(K$2<=$H18,"C","")))) | L18: =IF(L$2<$E18,"",IF(L$2<$F18,"D",IF(L$2<$G18,"C-",IF(L$2<=$H18,"C","")))) | M18: =IF(M$2<$E18,"",IF(M$2<$F18,"D",IF(M$2<$G18,"C-",IF(M$2<=$H18,"C","")))) | N18: =IF(N$2<$E18,"",IF(N$2<$F18,"D",IF(N$2<$G18,"C-",IF(N$2<=$H18,"C","")))) | O18: =IF(O$2<$E18,"",IF(O$2<$F18,"D",IF(O$2<$G18,"C-",IF(O$2<=$H18,"C","")))) | P18: =IF(P$2<$E18,"",IF(P$2<$F18,"D",IF(P$2<$G18,"C-",IF(P$2<=$H18,"C","")))) | ... AI18: =IF(AI$2<$E18,"",IF(AI$2<$F18,"D",IF(AI$2<$G18,"C-",IF(AI$2<=$H18,"C",""))))
A19: BESS 10 | B19: 10 | E19: 12 | F19: =G19 -> 15 | G19: =E19+3 -> 15 | H19: =G19+2 -> 17 | I19: =IF(I$2<$E19,"",IF(I$2<$F19,"D",IF(I$2<$G19,"C-",IF(I$2<=$H19,"C","")))) | J19: =IF(J$2<$E19,"",IF(J$2<$F19,"D",IF(J$2<$G19,"C-",IF(J$2<=$H19,"C","")))) | K19: =IF(K$2<$E19,"",IF(K$2<$F19,"D",IF(K$2<$G19,"C-",IF(K$2<=$H19,"C","")))) | L19: =IF(L$2<$E19,"",IF(L$2<$F19,"D",IF(L$2<$G19,"C-",IF(L$2<=$H19,"C","")))) | M19: =IF(M$2<$E19,"",IF(M$2<$F19,"D",IF(M$2<$G19,"C-",IF(M$2<=$H19,"C","")))) | N19: =IF(N$2<$E19,"",IF(N$2<$F19,"D",IF(N$2<$G19,"C-",IF(N$2<=$H19,"C","")))) | O19: =IF(O$2<$E19,"",IF(O$2<$F19,"D",IF(O$2<$G19,"C-",IF(O$2<=$H19,"C","")))) | P19: =IF(P$2<$E19,"",IF(P$2<$F19,"D",IF(P$2<$G19,"C-",IF(P$2<=$H19,"C","")))) | ... AI19: =IF(AI$2<$E19,"",IF(AI$2<$F19,"D",IF(AI$2<$G19,"C-",IF(AI$2<=$H19,"C",""))))
A21: CAPEX | B21: MW | C21: Max (M€/MW) | E21: Sum | F21: (M€/MW)
A22: DC 1 | B22: 4 | C22: 10 | E22: =SUM(I22:AI22) -> 30.500317 | F22: =E22/B22 -> 7.6250791 | K22: ='Sample DEC'!J58 -> 15.250158 | N22: ='Sample DEC'!M58 -> 12.650127 | S22: ='Sample DEC'!R58 -> 2.6000317 | U22: ='Sample DEC'!T58 -> 0 | V22: ='Sample DEC'!U58 -> 0 | AF22: ='Sample DEC'!V58 -> 0 | AG22: ='Sample DEC'!W58 -> 0 | AH22: ='Sample DEC'!X58 -> 0 | AI22: ='Sample DEC'!Y58 -> 0
A23: DC 2 | B23: 4 | C23: 9 | E23: =SUM(I23:AI23) -> 30.500317 | F23: =E23/B23 -> 7.6250791 | M23: =K22 -> 15.250158 | R23: =N22 -> 12.650127 | Y23: =S22 -> 2.6000317
A24: DC 3 | B24: 4 | C24: 9 | E24: =SUM(I24:AI24) -> 30.500317 | F24: =E24/B24 -> 7.6250791 | P24: =K22 -> 15.250158 | V24: =N22 -> 12.650127 | AD24: =S22 -> 2.6000317
A25: DC 4 | B25: 8 | C25: 9 | E25: =SUM(I25:AI25) -> 61.000633 | F25: =E25/B25 -> 7.6250791 | T25: =P24*2 -> 30.500317 | Z25: =N22*2 -> 25.300253 | AF25: =$S$22*2 -> 5.2000633
A26: DC 5 | B26: 8 | C26: 9 | E26: =SUM(I26:AI26) -> 61.000633 | F26: =E26/B26 -> 7.6250791 | T26: =T25 -> 30.500317 | Z26: =N22*2 -> 25.300253 | AF26: =$S$22*2 -> 5.2000633
A28: BESS 1 | B28: 5 | C28: 0.2 | E28: =SUM(I28:AI28) -> 2.511552 | F28: =E28/B28 -> 0.5023104 | J28: ='Sample BESS'!K21 -> 2.2723968 | O28: ='Sample BESS'!P21 -> 0.2391552
A29: BESS 2 | B29: 5 | C29: 0.2 | E29: =SUM(I29:AI29) -> 2.511552 | F29: =E29/B29 -> 0.5023104 | K29: =J28 -> 2.2723968 | P29: =O28 -> 0.2391552
A30: BESS 3 | B30: 5 | C30: 0.2 | E30: =SUM(I30:AI30) -> 2.511552 | F30: =E30/B30 -> 0.5023104 | M30: =$J$28 -> 2.2723968 | R30: =$O$28 -> 0.2391552
A31: BESS 4 | B31: 10 | C31: 0.2 | E31: =SUM(I31:AI31) -> 5.023104 | F31: =E31/B31 -> 0.5023104 | N31: =$J$28*2 -> 4.5447936 | S31: =$O$28*2 -> 0.4783104
A32: BESS 5 | B32: 10 | C32: 0.2 | E32: =SUM(I32:AI32) -> 5.023104 | F32: =E32/B32 -> 0.5023104 | O32: =$J$28*2 -> 4.5447936 | T32: =$O$28*2 -> 0.4783104
A33: BESS 6 | B33: 5 | C33: 0.2 | E33: =SUM(I33:AI33) -> 2.511552 | F33: =E33/B33 -> 0.5023104 | P33: =$J$28 -> 2.2723968 | U33: =$O$28 -> 0.2391552
A34: BESS 7 | B34: 10 | C34: 0.2 | E34: =SUM(I34:AI34) -> 5.023104 | F34: =E34/B34 -> 0.5023104 | Q34: =$J$28*2 -> 4.5447936 | V34: =$O$28*2 -> 0.4783104
A35: BESS 8 | B35: 10 | C35: 0.2 | E35: =SUM(I35:AI35) -> 5.023104 | F35: =E35/B35 -> 0.5023104 | R35: =$J$28*2 -> 4.5447936 | W35: =$O$28*2 -> 0.4783104
A36: BESS 9 | B36: 5 | C36: 0.2 | E36: =SUM(I36:AI36) -> 2.511552 | F36: =E36/B36 -> 0.5023104 | S36: =$J$28 -> 2.2723968 | X36: =$O$28 -> 0.2391552
A37: BESS 10 | B37: 10 | C37: 0.2 | E37: =SUM(I37:AI37) -> 5.023104 | F37: =E37/B37 -> 0.5023104 | T37: =$J$28*2 -> 4.5447936 | Y37: =$O$28*2 -> 0.4783104
A40: Total DC | I40: =SUM(I22:I26) -> 0 | J40: =SUM(J22:J26) -> 0 | K40: =SUM(K22:K26) -> 15.250158 | L40: =SUM(L22:L26) -> 0 | M40: =SUM(M22:M26) -> 15.250158 | N40: =SUM(N22:N26) -> 12.650127 | O40: =SUM(O22:O26) -> 0 | P40: =SUM(P22:P26) -> 15.250158 | ... AI40: =SUM(AI22:AI26) -> 0
A41: Total BESS | I41: =SUM(I28:I37) -> 0 | J41: =SUM(J28:J37) -> 2.2723968 | K41: =SUM(K28:K37) -> 2.2723968 | L41: =SUM(L28:L37) -> 0 | M41: =SUM(M28:M37) -> 2.2723968 | N41: =SUM(N28:N37) -> 4.5447936 | O41: =SUM(O28:O37) -> 4.7839488 | P41: =SUM(P28:P37) -> 2.511552 | ... AI41: =SUM(AI28:AI37) -> 0
A43: Grand total | F43: M€ | I43: =SUM(I40:I42) -> 0 | J43: =SUM(J40:J42) -> 2.2723968 | K43: =SUM(K40:K42) -> 17.522555 | L43: =SUM(L40:L42) -> 0 | M43: =SUM(M40:M42) -> 17.522555 | N43: =SUM(N40:N42) -> 17.19492 | O43: =SUM(O40:O42) -> 4.7839488 | P43: =SUM(P40:P42) -> 17.76171 | ... AI43: =SUM(AI40:AI42) -> 0
A45: FTE
A46: FTE EPC
...

Sheet Sample EPC Resources
A1: EPC Project Staffing Requirements
A3: With EPC contractor handling main execution, your team provides oversight and coordination
A5: Role | B5: FTE Required | C5: Responsibilities
A6: Legal | B6: 0.2 | C6: Contract review, compliance oversight, permit coordination
A7: Electrical Engineering | B7: 0.3 | C7: Design review, EPC coordination, testing oversight
A8: Construction Management | B8: 0.3 | C8: Site visits, progress monitoring, EPC liaison
A9: Water/MEP Systems | B9: 0.2 | C9: Cooling system review, water management oversight
A10: Planning & Coordination | B10: 0.4 | C10: Schedule tracking, milestone monitoring, stakeholder updates
A11: Quality Control | B11: 0.3 | C11: Inspection oversight, quality standards verification
A12: Procurement | B12: 0.2 | C12: Long-lead item tracking, vendor coordination
A14: Total | B14: =SUM(B6:B13) -> 1.9
A23: Role | B23: FTE Required | C23: Responsibilities | D23: NOTE
A24: Legal | B24: 0.2 | C24: Contract review, compliance oversight, permit coordination
A25: PM/Construction Manager | B25: 1 | C25: Site visits, progress monitoring, EPC liaison
A26: PM | B26: 1 | C26: Schedule tracking, milestone monitoring, stakeholder updates
A27: Quality Control | B27: 1 | C27: Inspection oversight, quality standards verification
A28: Procurement | B28: 0.5 | C28: Long-lead item tracking, vendor coordination
A30: Total | B30: =SUM(B24:B29) -> 3.7
D32: ONE TIME
D33: COORDINATION = PM, TEST = QC, Design = PROGRAM MANAGER
D34: PM / CONSTRUCTION MANAGER

Sheet Sample Non EPC Resources
A1: Self-Managed Project Staffing Requirements
A3: Full internal execution requiring comprehensive team across all disciplines
A5: Role | B5: FTE Required | C5: Responsibilities
A6: Legal | B6: 0.5 | C6: Contract negotiation, permitting, regulatory compliance, vendor agreements
A7: Electrical Engineering | B7: 1.5 | C7: Full design, power distribution, backup systems, testing & commissioning
A8: Construction Management | B8: 2 | C8: On-site supervision, contractor management, safety, schedule execution
A9: Water/MEP Systems | B9: 1 | C9: Cooling design, water treatment, HVAC systems, mechanical coordination
A10: Planning & Coordination | B10: 1 | C10: Master scheduling, resource allocation, critical path management
A11: Quality Control | B11: 1 | C11: Full inspection program, testing, documentation, standards enforcement
A12: Procurement | B12: 1.2 | C12: Vendor selection, negotiation, logistics, material tracking, cost control
A17: Total | B17: =SUM(B6:B16) -> 8.2
E23: Daily rate (external hire) per person | F23: Cost/day
A24: Role | B24: FTE Required | C24: Responsibilities
A25: Legal | B25: 0.5 | C25: Contract negotiation, permitting, regulatory compliance, vendor agreements | E25: 1000 | F25: =B25*E25 -> 500 | G25: =F25*21 -> 10500 | I25: =E25*21 -> 21000
A26: Electrical Engineering | B26: 1.5 | C26: Full design, power distribution, backup systems, testing & commissioning | E26: 1100 | F26: =B26*E26 -> 1650 | G26: =F26*21 -> 34650 | I26: =E26*21 -> 23100
A27: Construction Management | B27: 1 | C27: On-site supervision, contractor management, safety, schedule execution | E27: 1200 | F27: =B27*E27 -> 1200 | G27: =F27*21 -> 25200 | I27: =E27*21 -> 25200
A28: Water/MEP Systems | B28: 1 | C28: Cooling design, water treatment, HVAC systems, mechanical coordination | E28: 1100 | F28: =B28*E28 -> 1100 | G28: =F28*21 -> 23100 | I28: =E28*21 -> 23100
A29: Project Management | B29: 1 | C29: Master scheduling, resource allocation, critical path management | E29: 1500 | F29: =B29*E29 -> 1500 | G29: =F29*21 -> 31500 | I29: =E29*21 -> 31500
A30: Quality Control | B30: 1 | C30: Full inspection program, testing, documentation, standards enforcement | E30: 1000 | F30: =B30*E30 -> 1000 | G30: =F30*21 -> 21000 | I30: =E30*21 -> 21000
A31: Procurement | B31: 1.2 | C31: Vendor selection, negotiation, logistics, material tracking, cost control | E31: 900 | F31: =B31*E31 -> 1080 | G31: =F31*21 -> 22680 | I31: =E31*21 -> 18900
A32: HSE | B32: 1 | C32: Health and Safety Manager | E32: 800 | F32: =B32*E32 -> 800 | G32: =F32*21 -> 16800 | I32: =E32*21 -> 16800
A33: Security | B33: 7 | C33: During construction | E33: 400 | F33: =B33*E33 -> 2800 | G33: =F33*21 -> 58800 | I33: =E33*21 -> 8400
A34: Cost Control | B34: 1 | C34: Cost Control / adminstrative tasks | E34: 500 | F34: =B34*E34 -> 500 | G34: =F34*21 -> 10500 | I34: =E34*21 -> 10500
G35: =SUM(G25:G34) -> 254730
A36: Total | B36: =SUM(B25:B35) -> 16.2 | G36: =G35*12 -> 3056760
